<mujoco model="reacher">
	<asset>
		<texture builtin="gradient" height="256" rgb1=".9 .9 1." rgb2=".2 .3 .4" type="skybox" width="256"/>
		<texture name="texplane" builtin="checker" height="512" rgb1=".2 .3 .4" rgb2=".1 0.15 0.2" type="2d" width="512"/>
		<material name="floorplane" reflectance="0.5" texrepeat="1 1" texture="texplane" texuniform="true"/>
	</asset>
	<compiler angle="radian" inertiafromgeom="true"/>
	<default>
		<joint armature="1" damping="1" limited="true"/>
		<geom contype="0" friction="1 0.1 0.1" rgba="0.7 0.7 0 1"/>
	</default>
	<option gravity="0 0 -9.81" integrator="RK4" timestep="0.01"/>
	<worldbody>
		<!-- Arena -->
		<camera mode="fixed" name="robotview" pos="1.0 0 0.4" quat="0.653 0.271 0.271 0.653"/>
		<geom conaffinity="0" contype="0" material="floorplane" name="ground" pos="0 0 0" rgba="0.9 0.9 0.9 1" size="1 1 10" type="plane"/>
		<body name="table" pos="0 -0.2 0.075">
			<geom type="box" contype="1" size="0.25 0.2 0.075" rgba="0.4 0.4 0.4 1"/>
		</body>
		<light diffuse=".8 .8 .8" dir="0 -.15 -1" directional="false" pos="1 1 4.0" specular="0.3 0.3 0.3" castshadow="false"/>
    	<light diffuse=".8 .8 .8" dir="0 -.15 -1" directional="false" pos="-3. -3. 4.0" specular="0.3 0.3 0.3" castshadow="false"/>
		<body name="body0" pos="0 0 0">
			<geom conaffinity="2" contype="2" fromto="0 0 0 0 0 0.25" name="root" rgba="0.2 0.2 0.2 1" size=".01" type="capsule"/>
		</body>
		<!-- Particle -->
		<body name="fingertip" pos="0 0 0">
			<geom conaffinity="1" contype="1" name="fingertip" pos="0 0 0" rgba="0.1 0.4 0.9 1" size=".005" type="sphere"/>
			<joint axis="1 0 0" damping="0.1" name="sliderx" pos="0 0 0" type="slide" limited="true" range="-0.25 0.25"/>
			<joint axis="0 1 0" damping="0.1" name="slidery" pos="0 0 0" type="slide" limited="true" range="-0.4 0"/>
			<joint axis="0 0 1" damping="0.1" name="sliderz" pos="0 0 0" type="slide" limited="true" range="0.2 0.4"/>
		</body>
	</worldbody>
	<actuator>
		<velocity ctrllimited="true" ctrlrange="-1 1" gear="10" joint="sliderx"/>
		<velocity ctrllimited="true" ctrlrange="-1 1" gear="10" joint="slidery"/>
		<velocity ctrllimited="true" ctrlrange="-1 1" gear="10" joint="sliderz"/>
	</actuator>
</mujoco>